Workbook

Sheet 종목 기본정보
A1: 종목명 | B1: A전자 | C1: B건설 | D1: C증권 | E1: D화학 | F1: E엔터
A2: 상장주식수 | B2: 10000000 | C2: 5000000 | D2: 20000000 | E2: 1000000 | F2: 1000000
A3: 유동비율 | B3: 0.75 | C3: 0.9 | D3: 0.82 | E3: 0.88 | F3: 0.5

Sheet 일자별 주가
A1: 일자 | B1: A전자 | C1: B건설 | D1: C증권 | E1: D화학 | F1: E엔터
A2: 1 | B2: 10000 | C2: 20000 | D2: 30000 | E2: 100000 | F2: 1000000
A3: 2 | B3: =RANDBETWEEN(B2*0.97, B2*1.033) -> 9810 | C3: =RANDBETWEEN(C2*0.97, C2*1.033) -> 20628 | D3: =RANDBETWEEN(D2*0.97, D2*1.033) -> 29906 | E3: =RANDBETWEEN(E2*0.97, E2*1.033) -> 99801 | F3: =RANDBETWEEN(F2*0.97, F2*1.033) -> 991803
A4: 3 | B4: =RANDBETWEEN(B3*0.97, B3*1.033) -> 9681 | C4: =RANDBETWEEN(C3*0.97, C3*1.033) -> 20943 | D4: =RANDBETWEEN(D3*0.97, D3*1.033) -> 29437 | E4: =RANDBETWEEN(E3*0.97, E3*1.033) -> 98013 | F4: =RANDBETWEEN(F3*0.97, F3*1.033) -> 1012236
A5: 4 | B5: =RANDBETWEEN(B4*0.97, B4*1.033) -> 9902 | C5: =RANDBETWEEN(C4*0.97, C4*1.033) -> 20512 | D5: =RANDBETWEEN(D4*0.97, D4*1.033) -> 30373 | E5: =RANDBETWEEN(E4*0.97, E4*1.033) -> 98303 | F5: =RANDBETWEEN(F4*0.97, F4*1.033) -> 1034839
A6: 5 | B6: =RANDBETWEEN(B5*0.97, B5*1.033) -> 10006 | C6: =RANDBETWEEN(C5*0.97, C5*1.033) -> 20327 | D6: =RANDBETWEEN(D5*0.97, D5*1.033) -> 30868 | E6: =RANDBETWEEN(E5*0.97, E5*1.033) -> 100555 | F6: =RANDBETWEEN(F5*0.97, F5*1.033) -> 1053235
A7: 6 | B7: =RANDBETWEEN(B6*0.97, B6*1.033) -> 10310 | C7: =RANDBETWEEN(C6*0.97, C6*1.033) -> 20872 | D7: =RANDBETWEEN(D6*0.97, D6*1.033) -> 30294 | E7: =RANDBETWEEN(E6*0.97, E6*1.033) -> 100481 | F7: =RANDBETWEEN(F6*0.97, F6*1.033) -> 1029896
A8: 7 | B8: =RANDBETWEEN(B7*0.97, B7*1.033) -> 10291 | C8: =RANDBETWEEN(C7*0.97, C7*1.033) -> 20982 | D8: =RANDBETWEEN(D7*0.97, D7*1.033) -> 29779 | E8: =RANDBETWEEN(E7*0.97, E7*1.033) -> 99367 | F8: =RANDBETWEEN(F7*0.97, F7*1.033) -> 1048724
A9: 8 | B9: =RANDBETWEEN(B8*0.97, B8*1.033) -> 10380 | C9: =RANDBETWEEN(C8*0.97, C8*1.033) -> 21168 | D9: =RANDBETWEEN(D8*0.97, D8*1.033) -> 29204 | E9: =RANDBETWEEN(E8*0.97, E8*1.033) -> 97196 | F9: =RANDBETWEEN(F8*0.97, F8*1.033) -> 1027880
A10: 9 | B10: =RANDBETWEEN(B9*0.97, B9*1.033) -> 10127 | C10: =RANDBETWEEN(C9*0.97, C9*1.033) -> 21497 | D10: =RANDBETWEEN(D9*0.97, D9*1.033) -> 28379 | E10: =RANDBETWEEN(E9*0.97, E9*1.033) -> 96006 | F10: =RANDBETWEEN(F9*0.97, F9*1.033) -> 1048735
A11: 10 | B11: =RANDBETWEEN(B10*0.97, B10*1.033) -> 9888 | C11: =RANDBETWEEN(C10*0.97, C10*1.033) -> 21887 | D11: =RANDBETWEEN(D10*0.97, D10*1.033) -> 28266 | E11: =RANDBETWEEN(E10*0.97, E10*1.033) -> 97733 | F11: =RANDBETWEEN(F10*0.97, F10*1.033) -> 1020472
A12: 11 | B12: =RANDBETWEEN(B11*0.97, B11*1.033) -> 9695 | C12: =RANDBETWEEN(C11*0.97, C11*1.033) -> 21748 | D12: =RANDBETWEEN(D11*0.97, D11*1.033) -> 27711 | E12: =RANDBETWEEN(E11*0.97, E11*1.033) -> 95146 | F12: =RANDBETWEEN(F11*0.97, F11*1.033) -> 1033402
A13: 12 | B13: =RANDBETWEEN(B12*0.97, B12*1.033) -> 9603 | C13: =RANDBETWEEN(C12*0.97, C12*1.033) -> 21208 | D13: =RANDBETWEEN(D12*0.97, D12*1.033) -> 27540 | E13: =RANDBETWEEN(E12*0.97, E12*1.033) -> 97794 | F13: =RANDBETWEEN(F12*0.97, F12*1.033) -> 1043250
A14: 13 | B14: =RANDBETWEEN(B13*0.97, B13*1.033) -> 9494 | C14: =RANDBETWEEN(C13*0.97, C13*1.033) -> 20736 | D14: =RANDBETWEEN(D13*0.97, D13*1.033) -> 27474 | E14: =RANDBETWEEN(E13*0.97, E13*1.033) -> 96237 | F14: =RANDBETWEEN(F13*0.97, F13*1.033) -> 1012526
... A253: 252 | B253: =RANDBETWEEN(B252*0.97, B252*1.033) -> 19010 | C253: =RANDBETWEEN(C252*0.97, C252*1.033) -> 27047 | D253: =RANDBETWEEN(D252*0.97, D252*1.033) -> 21977 | E253: =RANDBETWEEN(E252*0.97, E252*1.033) -> 80393 | F253: =RANDBETWEEN(F252*0.97, F252*1.033) -> 1425885

Sheet 일자별 시가총액
A1: 일자 | B1: A전자 | C1: B건설 | D1: C증권 | E1: D화학 | F1: E엔터 | G1: 합계 | H1: 지수
A2: 1 | B2: ='일자별 주가'!B2*'종목 기본정보'!B$2*'종목 기본정보'!B$3 -> 75000000000 | C2: ='일자별 주가'!C2*'종목 기본정보'!C$2*'종목 기본정보'!C$3 -> 90000000000 | D2: ='일자별 주가'!D2*'종목 기본정보'!D$2*'종목 기본정보'!D$3 -> 492000000000 | E2: ='일자별 주가'!E2*'종목 기본정보'!E$2*'종목 기본정보'!E$3 -> 88000000000 | F2: ='일자별 주가'!F2*'종목 기본정보'!F$2*'종목 기본정보'!F$3 -> 500000000000 | G2: =SUM(B2:F2) -> 1245000000000 | H2: =G2/G$2*100 -> 100
A3: 2 | B3: ='일자별 주가'!B3*'종목 기본정보'!B$2*'종목 기본정보'!B$3 -> 73575000000 | C3: ='일자별 주가'!C3*'종목 기본정보'!C$2*'종목 기본정보'!C$3 -> 92826000000 | D3: ='일자별 주가'!D3*'종목 기본정보'!D$2*'종목 기본정보'!D$3 -> 490458400000 | E3: ='일자별 주가'!E3*'종목 기본정보'!E$2*'종목 기본정보'!E$3 -> 87824880000 | F3: ='일자별 주가'!F3*'종목 기본정보'!F$2*'종목 기본정보'!F$3 -> 495901500000 | G3: =SUM(B3:F3) -> 1240585780000 | H3: =G3/G$2*100 -> 99.645444
A4: 3 | B4: ='일자별 주가'!B4*'종목 기본정보'!B$2*'종목 기본정보'!B$3 -> 72607500000 | C4: ='일자별 주가'!C4*'종목 기본정보'!C$2*'종목 기본정보'!C$3 -> 94243500000 | D4: ='일자별 주가'!D4*'종목 기본정보'!D$2*'종목 기본정보'!D$3 -> 482766800000 | E4: ='일자별 주가'!E4*'종목 기본정보'!E$2*'종목 기본정보'!E$3 -> 86251440000 | F4: ='일자별 주가'!F4*'종목 기본정보'!F$2*'종목 기본정보'!F$3 -> 506118000000 | G4: =SUM(B4:F4) -> 1241987240000 | H4: =G4/G$2*100 -> 99.758011
A5: 4 | B5: ='일자별 주가'!B5*'종목 기본정보'!B$2*'종목 기본정보'!B$3 -> 74265000000 | C5: ='일자별 주가'!C5*'종목 기본정보'!C$2*'종목 기본정보'!C$3 -> 92304000000 | D5: ='일자별 주가'!D5*'종목 기본정보'!D$2*'종목 기본정보'!D$3 -> 498117200000 | E5: ='일자별 주가'!E5*'종목 기본정보'!E$2*'종목 기본정보'!E$3 -> 86506640000 | F5: ='일자별 주가'!F5*'종목 기본정보'!F$2*'종목 기본정보'!F$3 -> 517419500000 | G5: =SUM(B5:F5) -> 1268612340000 | H5: =G5/G$2*100 -> 101.89657
A6: 5 | B6: ='일자별 주가'!B6*'종목 기본정보'!B$2*'종목 기본정보'!B$3 -> 75045000000 | C6: ='일자별 주가'!C6*'종목 기본정보'!C$2*'종목 기본정보'!C$3 -> 91471500000 | D6: ='일자별 주가'!D6*'종목 기본정보'!D$2*'종목 기본정보'!D$3 -> 506235200000 | E6: ='일자별 주가'!E6*'종목 기본정보'!E$2*'종목 기본정보'!E$3 -> 88488400000 | F6: ='일자별 주가'!F6*'종목 기본정보'!F$2*'종목 기본정보'!F$3 -> 526617500000 | G6: =SUM(B6:F6) -> 1287857600000 | H6: =G6/G$2*100 -> 103.44238
A7: 6 | B7: ='일자별 주가'!B7*'종목 기본정보'!B$2*'종목 기본정보'!B$3 -> 77325000000 | C7: ='일자별 주가'!C7*'종목 기본정보'!C$2*'종목 기본정보'!C$3 -> 93924000000 | D7: ='일자별 주가'!D7*'종목 기본정보'!D$2*'종목 기본정보'!D$3 -> 496821600000 | E7: ='일자별 주가'!E7*'종목 기본정보'!E$2*'종목 기본정보'!E$3 -> 88423280000 | F7: ='일자별 주가'!F7*'종목 기본정보'!F$2*'종목 기본정보'!F$3 -> 514948000000 | G7: =SUM(B7:F7) -> 1271441880000 | H7: =G7/G$2*100 -> 102.12385
A8: 7 | B8: ='일자별 주가'!B8*'종목 기본정보'!B$2*'종목 기본정보'!B$3 -> 77182500000 | C8: ='일자별 주가'!C8*'종목 기본정보'!C$2*'종목 기본정보'!C$3 -> 94419000000 | D8: ='일자별 주가'!D8*'종목 기본정보'!D$2*'종목 기본정보'!D$3 -> 488375600000 | E8: ='일자별 주가'!E8*'종목 기본정보'!E$2*'종목 기본정보'!E$3 -> 87442960000 | F8: ='일자별 주가'!F8*'종목 기본정보'!F$2*'종목 기본정보'!F$3 -> 524362000000 | G8: =SUM(B8:F8) -> 1271782060000 | H8: =G8/G$2*100 -> 102.15117
A9: 8 | B9: ='일자별 주가'!B9*'종목 기본정보'!B$2*'종목 기본정보'!B$3 -> 77850000000 | C9: ='일자별 주가'!C9*'종목 기본정보'!C$2*'종목 기본정보'!C$3 -> 95256000000 | D9: ='일자별 주가'!D9*'종목 기본정보'!D$2*'종목 기본정보'!D$3 -> 478945600000 | E9: ='일자별 주가'!E9*'종목 기본정보'!E$2*'종목 기본정보'!E$3 -> 85532480000 | F9: ='일자별 주가'!F9*'종목 기본정보'!F$2*'종목 기본정보'!F$3 -> 513940000000 | G9: =SUM(B9:F9) -> 1251524080000 | H9: =G9/G$2*100 -> 100.52402
A10: 9 | B10: ='일자별 주가'!B10*'종목 기본정보'!B$2*'종목 기본정보'!B$3 -> 75952500000 | C10: ='일자별 주가'!C10*'종목 기본정보'!C$2*'종목 기본정보'!C$3 -> 96736500000 | D10: ='일자별 주가'!D10*'종목 기본정보'!D$2*'종목 기본정보'!D$3 -> 465415600000 | E10: ='일자별 주가'!E10*'종목 기본정보'!E$2*'종목 기본정보'!E$3 -> 84485280000 | F10: ='일자별 주가'!F10*'종목 기본정보'!F$2*'종목 기본정보'!F$3 -> 524367500000 | G10: =SUM(B10:F10) -> 1246957380000 | H10: =G10/G$2*100 -> 100.15722
A11: 10 | B11: ='일자별 주가'!B11*'종목 기본정보'!B$2*'종목 기본정보'!B$3 -> 74160000000 | C11: ='일자별 주가'!C11*'종목 기본정보'!C$2*'종목 기본정보'!C$3 -> 98491500000 | D11: ='일자별 주가'!D11*'종목 기본정보'!D$2*'종목 기본정보'!D$3 -> 463562400000 | E11: ='일자별 주가'!E11*'종목 기본정보'!E$2*'종목 기본정보'!E$3 -> 86005040000 | F11: ='일자별 주가'!F11*'종목 기본정보'!F$2*'종목 기본정보'!F$3 -> 510236000000 | G11: =SUM(B11:F11) -> 1232454940000 | H11: =G11/G$2*100 -> 98.992365
A12: 11 | B12: ='일자별 주가'!B12*'종목 기본정보'!B$2*'종목 기본정보'!B$3 -> 72712500000 | C12: ='일자별 주가'!C12*'종목 기본정보'!C$2*'종목 기본정보'!C$3 -> 97866000000 | D12: ='일자별 주가'!D12*'종목 기본정보'!D$2*'종목 기본정보'!D$3 -> 454460400000 | E12: ='일자별 주가'!E12*'종목 기본정보'!E$2*'종목 기본정보'!E$3 -> 83728480000 | F12: ='일자별 주가'!F12*'종목 기본정보'!F$2*'종목 기본정보'!F$3 -> 516701000000 | G12: =SUM(B12:F12) -> 1225468380000 | H12: =G12/G$2*100 -> 98.431195
A13: 12 | B13: ='일자별 주가'!B13*'종목 기본정보'!B$2*'종목 기본정보'!B$3 -> 72022500000 | C13: ='일자별 주가'!C13*'종목 기본정보'!C$2*'종목 기본정보'!C$3 -> 95436000000 | D13: ='일자별 주가'!D13*'종목 기본정보'!D$2*'종목 기본정보'!D$3 -> 451656000000 | E13: ='일자별 주가'!E13*'종목 기본정보'!E$2*'종목 기본정보'!E$3 -> 86058720000 | F13: ='일자별 주가'!F13*'종목 기본정보'!F$2*'종목 기본정보'!F$3 -> 521625000000 | G13: =SUM(B13:F13) -> 1226798220000 | H13: =G13/G$2*100 -> 98.53801
... A253: 252 | B253: ='일자별 주가'!B253*'종목 기본정보'!B$2*'종목 기본정보'!B$3 -> 142575000000 | C253: ='일자별 주가'!C253*'종목 기본정보'!C$2*'종목 기본정보'!C$3 -> 121711500000 | D253: ='일자별 주가'!D253*'종목 기본정보'!D$2*'종목 기본정보'!D$3 -> 360422800000 | E253: ='일자별 주가'!E253*'종목 기본정보'!E$2*'종목 기본정보'!E$3 -> 70745840000 | F253: ='일자별 주가'!F253*'종목 기본정보'!F$2*'종목 기본정보'!F$3 -> 712942500000 | G253: =SUM(B253:F253) -> 1408397640000 | H253: =G253/G$2*100 -> 113.12431

Sheet 선물
A1: 일자 | B1: 지수 | C1: 선물이론가(1분기) | D1: 선물이론가(2분기)
A2: 1 | B2: ='일자별 시가총액'!H2 -> 100 | C2: =B2*EXP(($G$2-$G$3)*(($G$4-A2)/252)) -> 100.18469 | D2: =B2*EXP(($G$2-$G$3)*(($G$5-A2)/252)) -> 100.37272 | F2: 이자율 | G2: 0.0225 | H2: 기준 국고채 금리(무위험이자율)
A3: 2 | B3: ='일자별 시가총액'!H3 -> 99.645444 | C3: =B3*EXP(($G$2-$G$3)*(($G$4-A3)/252)) -> 99.826512 | D3: =B3*EXP(($G$2-$G$3)*(($G$5-A3)/252)) -> 100.01386 | F3: 배당률 | G3: 0.015 | H3: KOSPI200 평균 배당률
A4: 3 | B4: ='일자별 시가총액'!H4 -> 99.758011 | C4: =B4*EXP(($G$2-$G$3)*(($G$4-A4)/252)) -> 99.93631 | D4: =B4*EXP(($G$2-$G$3)*(($G$5-A4)/252)) -> 100.12387 | F4: 만기(1분기) | G4: 63
A5: 4 | B5: ='일자별 시가총액'!H5 -> 101.89657 | C5: =B5*EXP(($G$2-$G$3)*(($G$4-A5)/252)) -> 102.07566 | D5: =B5*EXP(($G$2-$G$3)*(($G$5-A5)/252)) -> 102.26723 | F5: 만기(분기) | G5: 126
A6: 5 | B6: ='일자별 시가총액'!H6 -> 103.44238 | C6: =B6*EXP(($G$2-$G$3)*(($G$4-A6)/252)) -> 103.62109 | D6: =B6*EXP(($G$2-$G$3)*(($G$5-A6)/252)) -> 103.81556
A7: 6 | B7: ='일자별 시가총액'!H7 -> 102.12385 | C7: =B7*EXP(($G$2-$G$3)*(($G$4-A7)/252)) -> 102.29724 | D7: =B7*EXP(($G$2-$G$3)*(($G$5-A7)/252)) -> 102.48923
A8: 7 | B8: ='일자별 시가총액'!H8 -> 102.15117 | C8: =B8*EXP(($G$2-$G$3)*(($G$4-A8)/252)) -> 102.32156 | D8: =B8*EXP(($G$2-$G$3)*(($G$5-A8)/252)) -> 102.5136
A9: 8 | B9: ='일자별 시가총액'!H9 -> 100.52402 | C9: =B9*EXP(($G$2-$G$3)*(($G$4-A9)/252)) -> 100.68871 | D9: =B9*EXP(($G$2-$G$3)*(($G$5-A9)/252)) -> 100.87767
A10: 9 | B10: ='일자별 시가총액'!H10 -> 100.15722 | C10: =B10*EXP(($G$2-$G$3)*(($G$4-A10)/252)) -> 100.31832 | D10: =B10*EXP(($G$2-$G$3)*(($G$5-A10)/252)) -> 100.50659
A11: 10 | B11: ='일자별 시가총액'!H11 -> 98.992365 | C11: =B11*EXP(($G$2-$G$3)*(($G$4-A11)/252)) -> 99.148637 | D11: =B11*EXP(($G$2-$G$3)*(($G$5-A11)/252)) -> 99.334715
A12: 11 | B12: ='일자별 시가총액'!H12 -> 98.431195 | C12: =B12*EXP(($G$2-$G$3)*(($G$4-A12)/252)) -> 98.583647 | D12: =B12*EXP(($G$2-$G$3)*(($G$5-A12)/252)) -> 98.768665
A13: 12 | B13: ='일자별 시가총액'!H13 -> 98.53801 | C13: =B13*EXP(($G$2-$G$3)*(($G$4-A13)/252)) -> 98.68769 | D13: =B13*EXP(($G$2-$G$3)*(($G$5-A13)/252)) -> 98.872903
A14: 13 | B14: ='일자별 시가총액'!H14 -> 96.870856 | C14: =B14*EXP(($G$2-$G$3)*(($G$4-A14)/252)) -> 97.015117 | D14: =B14*EXP(($G$2-$G$3)*(($G$5-A14)/252)) -> 97.197191
A15: 14 | B15: ='일자별 시가총액'!H15 -> 96.92528 | C15: =B15*EXP(($G$2-$G$3)*(($G$4-A15)/252)) -> 97.066733 | D15: =B15*EXP(($G$2-$G$3)*(($G$5-A15)/252)) -> 97.248904
A16: 15 | B16: ='일자별 시가총액'!H16 -> 95.949892 | C16: =B16*EXP(($G$2-$G$3)*(($G$4-A16)/252)) -> 96.087062 | D16: =B16*EXP(($G$2-$G$3)*(($G$5-A16)/252)) -> 96.267394
A17: 16 | B17: ='일자별 시가총액'!H17 -> 96.71026 | C17: =B17*EXP(($G$2-$G$3)*(($G$4-A17)/252)) -> 96.845634 | D17: =B17*EXP(($G$2-$G$3)*(($G$5-A17)/252)) -> 97.02739
... A64: 63 | B64: ='일자별 시가총액'!H64 -> 96.382227 | C64: =B64*EXP(($G$2-$G$3)*(($G$4-A64)/252)) -> 96.382227 | D64: =B64*EXP(($G$2-$G$3)*(($G$5-A64)/252)) -> 96.563113
A65: 64 | B65: ='일자별 시가총액'!H65 -> 97.061113 | D65: =B65*EXP(($G$2-$G$3)*(($G$5-A65)/252)) -> 97.240379
A66: 65 | B66: ='일자별 시가총액'!H66 -> 96.275046 | D66: =B66*EXP(($G$2-$G$3)*(($G$5-A66)/252)) -> 96.44999
A67: 66 | B67: ='일자별 시가총액'!H67 -> 95.590238 | D67: =B67*EXP(($G$2-$G$3)*(($G$5-A67)/252)) -> 95.761087
A68: 67 | B68: ='일자별 시가총액'!H68 -> 96.617545 | D68: =B68*EXP(($G$2-$G$3)*(($G$5-A68)/252)) -> 96.78735
A69: 68 | B69: ='일자별 시가총액'!H69 -> 96.477944 | D69: =B69*EXP(($G$2-$G$3)*(($G$5-A69)/252)) -> 96.644627
A70: 69 | B70: ='일자별 시가총액'!H70 -> 97.522941 | D70: =B70*EXP(($G$2-$G$3)*(($G$5-A70)/252)) -> 97.688522
A71: 70 | B71: ='일자별 시가총액'!H71 -> 97.34596 | D71: =B71*EXP(($G$2-$G$3)*(($G$5-A71)/252)) -> 97.508338
A72: 71 | B72: ='일자별 시가총액'!H72 -> 97.700585 | D72: =B72*EXP(($G$2-$G$3)*(($G$5-A72)/252)) -> 97.860642
A73: 72 | B73: ='일자별 시가총액'!H73 -> 98.4245 | D73: =B73*EXP(($G$2-$G$3)*(($G$5-A73)/252)) -> 98.582809
A74: 73 | B74: ='일자별 시가총액'!H74 -> 98.388789 | D74: =B74*EXP(($G$2-$G$3)*(($G$5-A74)/252)) -> 98.544108
A75: 74 | B75: ='일자별 시가총액'!H75 -> 100.12947 | D75: =B75*EXP(($G$2-$G$3)*(($G$5-A75)/252)) -> 100.28455
A76: 75 | B76: ='일자별 시가총액'!H76 -> 100.26805 | D76: =B76*EXP(($G$2-$G$3)*(($G$5-A76)/252)) -> 100.42036
... A127: 126 | B127: ='일자별 시가총액'!H127 -> 102.86988 | D127: =B127*EXP(($G$2-$G$3)*(($G$5-A127)/252)) -> 102.86988
A128: 127 | B128: ='일자별 시가총액'!H128 -> 103.63172
A129: 128 | B129: ='일자별 시가총액'!H129 -> 102.78346
A130: 129 | B130: ='일자별 시가총액'!H130 -> 101.74095
A131: 130 | B131: ='일자별 시가총액'!H131 -> 102.06616
A132: 131 | B132: ='일자별 시가총액'!H132 -> 100.40556
A133: 132 | B133: ='일자별 시가총액'!H133 -> 101.98506
A134: 133 | B134: ='일자별 시가총액'!H134 -> 102.65346
A135: 134 | B135: ='일자별 시가총액'!H135 -> 102.89153
A136: 135 | B136: ='일자별 시가총액'!H136 -> 104.79906
...
